<robot name="hunter_pltf">
  <link name="base_link"/>
  <joint name="chassis_joint" type="fixed">
    <parent link="base_link"/>
    <child link="chassis"/>
    <origin rpy="0 0 0" xyz="0 0 0.37"/>
  </joint>
  <link name="chassis">
    <visual>
      <origin rpy="0 0 0" xyz="0 0 0"/>
      <geometry>
        <mesh filename="file:///home/ros/aoc_strawberry_scenario_ws/install/gazebo_multisim_server/share/gazebo_multisim_server/meshes/chassis.dae"/>
      </geometry>
    </visual>
    <collision>
      <origin rpy="0 0 0" xyz="0 0 0"/>
      <geometry>
        <mesh filename="file:///home/ros/aoc_strawberry_scenario_ws/install/gazebo_multisim_server/share/gazebo_multisim_server/meshes/chassis.dae"/>
      </geometry>
    </collision>
    <inertial>
      <origin rpy="0 0 0" xyz="0.0266989327622036 0.000409203500587652 -0.135901124750884"/>
      <mass value="72"/>
      <inertia ixx="0.0332370959804736" ixy="-1.013150489971E-06" ixz="-0.00188859201421112" iyy="0.111072002332437" iyz="-5.13308150598312E-07" izz="0.12660862809283"/>
    </inertial>
  </link>
  <link name="rear_left_wheel">
    <visual>
      <origin rpy="0 0 0" xyz="0 0 0"/>
      <geometry>
        <mesh filename="file:///home/ros/aoc_strawberry_scenario_ws/install/gazebo_multisim_server/share/gazebo_multisim_server/meshes/rear_left_wheel.dae"/>
      </geometry>
    </visual>
    <collision>
      <origin rpy="0 0 0" xyz="0 0 0"/>
      <geometry>
        <mesh filename="file:///home/ros/aoc_strawberry_scenario_ws/install/gazebo_multisim_server/share/gazebo_multisim_server/meshes/rear_left_wheel.dae"/>
      </geometry>
    </collision>
    <inertial>
      <origin rpy="0 0 0" xyz="-6.5774E-06 2.0242E-05 -0.0096386"/>
      <mass value="7.0"/>
      <inertia ixx="0.063724" ixy="0" ixz="0" iyy="0.063724" iyz="0" izz="0.11072"/>
    </inertial>
  </link>
  <joint name="rear_left_wheel_joint" type="continuous">
    <parent link="chassis"/>
    <child link="rear_left_wheel"/>
    <origin rpy="1.5707963267948966 0 0" xyz="-0.28 0.2925 -0.19558"/>
    <axis xyz="0 0 -1"/>
    <dynamics damping="0.2" friction="15"/>
    <limit effort="10.0" velocity="10.0"/>
  </joint>
  <gazebo reference="rear_left_wheel">
    <mu1 value="1.0"/>
    <mu2 value="0.5"/>
    <kp value="10000000.0"/>
    <kd value="1.0"/>
    <fdir1 value="1 0 0"/>
  </gazebo>
  <link name="rear_right_wheel">
    <visual>
      <origin rpy="0 0 0" xyz="0 0 0"/>
      <geometry>
        <mesh filename="file:///home/ros/aoc_strawberry_scenario_ws/install/gazebo_multisim_server/share/gazebo_multisim_server/meshes/rear_right_wheel.dae"/>
      </geometry>
    </visual>
    <collision>
      <origin rpy="0 0 0" xyz="0 0 0"/>
      <geometry>
        <mesh filename="file:///home/ros/aoc_strawberry_scenario_ws/install/gazebo_multisim_server/share/gazebo_multisim_server/meshes/rear_right_wheel.dae"/>
      </geometry>
    </collision>
    <inertial>
      <origin rpy="0 0 0" xyz="-6.5774E-06 2.0242E-05 -0.0096386"/>
      <mass value="7.0"/>
      <inertia ixx="0.063724" ixy="0" ixz="0" iyy="0.063724" iyz="0" izz="0.11072"/>
    </inertial>
  </link>
  <joint name="rear_right_wheel_joint" type="continuous">
    <parent link="chassis"/>
    <child link="rear_right_wheel"/>
    <origin rpy="1.5707963267948966 0 0" xyz="-0.28 -0.2925 -0.19558"/>
    <axis xyz="0 0 -1"/>
    <dynamics damping="0.2" friction="15"/>
    <limit effort="10.0" velocity="10.0"/>
    <mimic joint="rear_left_wheel_joint" multiplier="1.0" offset="0.0"/>
  </joint>
  <gazebo reference="rear_right_wheel">
    <mu1 value="1.0"/>
    <mu2 value="0.5"/>
    <kp value="10000000.0"/>
    <kd value="1.0"/>
    <fdir1 value="1 0 0"/>
  </gazebo>
  <link name="front_left_steering_link">
    <visual>
      <origin rpy="0 0 0" xyz="0 0 0"/>
      <geometry>
        <cylinder length="0.01" radius="0.01"/>
      </geometry>
      <material name="invisible">
        <color rgba="0.0 0.0 0.0 0.0"/>
      </material>
    </visual>
    <inertial>
      <origin rpy="0 0 0" xyz="0 0 0"/>
      <mass value="0.005"/>
      <inertia ixx="0.1" ixy="0" ixz="0" iyy="0.1" iyz="0" izz="0.1"/>
    </inertial>
  </link>
  <joint name="front_left_steering_joint" type="revolute">
    <parent link="chassis"/>
    <child link="front_left_steering_link"/>
    <origin rpy="1.5707963267948966 0 0" xyz="0.37142 0.2925 -0.19558"/>
    <axis xyz="0 1 0"/>
    <limit effort="10.0" lower="-0.461" upper="0.461" velocity="1"/>
    <dynamics damping="0.2"/>
  </joint>
  <link name="front_left_wheel">
    <visual>
      <origin rpy="0 0 0" xyz="0 0 0"/>
      <geometry>
        <mesh filename="file:///home/ros/aoc_strawberry_scenario_ws/install/gazebo_multisim_server/share/gazebo_multisim_server/meshes/front_left_wheel.dae"/>
      </geometry>
    </visual>
    <collision>
      <origin rpy="0 0 0" xyz="0 0 0"/>
      <geometry>
        <mesh filename="file:///home/ros/aoc_strawberry_scenario_ws/install/gazebo_multisim_server/share/gazebo_multisim_server/meshes/front_left_wheel.dae"/>
      </geometry>
    </collision>
    <inertial>
      <origin rpy="0 0 0" xyz="-6.5774E-06 2.0242E-05 -0.0096386"/>
      <mass value="7.0"/>
      <inertia ixx="0.063724" ixy="0" ixz="0" iyy="0.063724" iyz="0" izz="0.11072"/>
    </inertial>
  </link>
  <joint name="front_left_wheel_joint" type="continuous">
    <parent link="front_left_steering_link"/>
    <child link="front_left_wheel"/>
    <origin rpy="0 0 0" xyz="0 0 0"/>
    <axis xyz="0 0 -1"/>
  </joint>
  <link name="front_right_steering_link">
    <visual>
      <origin rpy="0 0 0" xyz="0 0 0"/>
      <geometry>
        <cylinder length="0.01" radius="0.01"/>
      </geometry>
      <material name="invisible">
        <color rgba="0.0 0.0 0.0 0.0"/>
      </material>
    </visual>
    <inertial>
      <origin rpy="0 0 0" xyz="0 0 0"/>
      <mass value="0.005"/>
      <inertia ixx="0.1" ixy="0" ixz="0" iyy="0.1" iyz="0" izz="0.1"/>
    </inertial>
  </link>
  <joint name="front_right_steering_joint" type="revolute">
    <parent link="chassis"/>
    <child link="front_right_steering_link"/>
    <origin rpy="1.5707963267948966 0 0" xyz="0.37142  -0.2925 -0.19558"/>
    <axis xyz="0 1 0"/>
    <limit effort="10.0" lower="-0.461" upper="0.461" velocity="1"/>
    <dynamics damping="0.2"/>
    <mimic joint="front_left_steering_joint" multiplier="1.0" offset="0.0"/>
  </joint>
  <link name="front_right_wheel">
    <visual>
      <origin rpy="0 0 0" xyz="0 0 0"/>
      <geometry>
        <mesh filename="file:///home/ros/aoc_strawberry_scenario_ws/install/gazebo_multisim_server/share/gazebo_multisim_server/meshes/front_right_wheel.dae"/>
      </geometry>
    </visual>
    <collision>
      <origin rpy="0 0 0" xyz="0 0 0"/>
      <geometry>
        <mesh filename="file:///home/ros/aoc_strawberry_scenario_ws/install/gazebo_multisim_server/share/gazebo_multisim_server/meshes/front_right_wheel.dae"/>
      </geometry>
    </collision>
    <inertial>
      <origin rpy="0 0 0" xyz="-6.5774E-06 2.0242E-05 -0.0096386"/>
      <mass value="7.0"/>
      <inertia ixx="0.063724" ixy="0" ixz="0" iyy="0.063724" iyz="0" izz="0.11072"/>
    </inertial>
  </link>
  <joint name="front_right_wheel_joint" type="continuous">
    <parent link="front_right_steering_link"/>
    <child link="front_right_wheel"/>
    <origin rpy="0 0 0" xyz="0 0 0"/>
    <axis xyz="0 0 -1"/>
  </joint>
  <ros2_control name="GazeboSystem" type="system">
    <hardware>
      <plugin>gazebo_ros2_control/GazeboSystem</plugin>
    </hardware>
    <joint name="front_left_steering_joint">
      <command_interface name="position"/>
      <state_interface name="position"/>
    </joint>
    <joint name="front_right_steering_joint">
      <param name="mimic">front_left_steering_joint</param>
      <param name="multiplier">1</param>
      <state_interface name="position"/>
    </joint>
    <joint name="rear_left_wheel_joint">
      <command_interface name="velocity"/>
      <state_interface name="velocity"/>
      <state_interface name="position"/>
    </joint>
    <joint name="rear_right_wheel_joint">
      <param name="mimic">rear_left_wheel_joint</param>
      <param name="multiplier">1</param>
      <state_interface name="velocity"/>
      <state_interface name="position"/>
    </joint>
    <joint name="front_right_wheel_joint">
      <state_interface name="velocity"/>
      <state_interface name="position"/>
    </joint>
    <joint name="front_left_wheel_joint">
      <state_interface name="velocity"/>
      <state_interface name="position"/>
    </joint>
  </ros2_control>
  <gazebo>
    <plugin filename="libgazebo_ros2_control.so" name="gazebo_ros2_control">
      <parameters>/home/ros/aoc_strawberry_scenario_ws/install/gazebo_multisim_server/share/gazebo_multisim_server/config/ackermann_like_controller.yaml</parameters>
    </plugin>
  </gazebo>
  <joint name="imu1_joint" type="fixed">
    <parent link="base_link"/>
    <child link="imu1_link"/>
    <origin rpy="0.0 0.0 0.0" xyz="0.0 0.0 0.2"/>
  </joint>
  <link name="imu1_link"/>
  <gazebo reference="imu1_link">
    <sensor name="imu1_imu" type="imu">
      <plugin filename="libgazebo_ros_imu_sensor.so" name="imu1_controller">
        <ros>
          <remapping>~/out:=gps_base/yaw</remapping>
          <initial_orientation_as_reference>false</initial_orientation_as_reference>
        </ros>
        <frame_name>imu1_link</frame_name>
      </plugin>
      <always_on>true</always_on>
      <update_rate>50</update_rate>
      <imu>
        <angular_velocity>
          <noise type="gaussian">
            <mean>0.0</mean>
            <stddev>0.01</stddev>
          </noise>
          <bias>
            <mean>0.0</mean>
            <stddev>0.0001</stddev>
          </bias>
        </angular_velocity>
        <linear_acceleration>
          <noise type="gaussian">
            <mean>0.0</mean>
            <stddev>0.01</stddev>
          </noise>
          <bias>
            <mean>0.0</mean>
            <stddev>0.0001</stddev>
          </bias>
        </linear_acceleration>
      </imu>
    </sensor>
  </gazebo>
  <joint name="front_camera_camera_joint" type="fixed">
    <parent link="base_link"/>
    <child link="front_camera_link"/>
    <origin rpy="0.0 0.0 0.0" xyz="0.55 -0.0 0.5"/>
  </joint>
  <link name="front_camera_link">
    <visual>
      <origin rpy="0 0 -1.57" xyz="0 0 0"/>
      <geometry>
        <mesh filename="file:///home/ros/aoc_strawberry_scenario_ws/install/gazebo_multisim_server/share/gazebo_multisim_server/meshes/zed2.dae"/>
      </geometry>
    </visual>
  </link>
  <joint name="front_camera_optical_joint" type="fixed">
    <parent link="front_camera_link"/>
    <child link="front_camera_link_optical"/>
    <origin rpy="-1.5707963267948966 0 -1.5707963267948966" xyz="0 0 0"/>
  </joint>
  <link name="front_camera_link_optical"/>
  <gazebo reference="front_camera_link">
    <sensor name="front_camera_camera" type="depth">
      <pose> 0 0 0 0 0 0 </pose>
      <visualize>true</visualize>
      <update_rate>10</update_rate>
      <camera>
        <horizontal_fov>2.089</horizontal_fov>
        <image>
          <format>B8G8R8</format>
          <width>640</width>
          <height>480</height>
        </image>
        <clip>
          <near>0.05</near>
          <far>8.0</far>
        </clip>
      </camera>
      <plugin filename="libgazebo_ros_camera.so" name="front_camera_camera_controller">
        <camera_name>front_camera</camera_name>
        <frame_name>front_camera_link_optical</frame_name>
        <hack_baseline>0.07</hack_baseline>
        <min_depth>0.4</min_depth>
        <max_depth>6</max_depth>
        <ros>
          
          <qos>
            <topic name="front_camera/points">
              <publisher>
                <reliability>best_effort</reliability>
                <!-- Change to 'best_effort' -->
                <durability>volatile</durability>
                <!-- Optionally set durability -->
              </publisher>
            </topic>
          </qos>
        </ros>
      </plugin>
    </sensor>
  </gazebo>
  <joint name="back_camera_camera_joint" type="fixed">
    <parent link="base_link"/>
    <child link="back_camera_link"/>
    <origin rpy="0.0 0.0 3.14" xyz="-0.55 -0.0 0.5"/>
  </joint>
  <link name="back_camera_link">
    <visual>
      <origin rpy="0 0 -1.57" xyz="0 0 0"/>
      <geometry>
        <mesh filename="file:///home/ros/aoc_strawberry_scenario_ws/install/gazebo_multisim_server/share/gazebo_multisim_server/meshes/zed2.dae"/>
      </geometry>
    </visual>
  </link>
  <joint name="back_camera_optical_joint" type="fixed">
    <parent link="back_camera_link"/>
    <child link="back_camera_link_optical"/>
    <origin rpy="-1.5707963267948966 0 -1.5707963267948966" xyz="0 0 0"/>
  </joint>
  <link name="back_camera_link_optical"/>
  <gazebo reference="back_camera_link">
    <sensor name="back_camera_camera" type="depth">
      <pose> 0 0 0 0 0 0 </pose>
      <visualize>true</visualize>
      <update_rate>10</update_rate>
      <camera>
        <horizontal_fov>2.089</horizontal_fov>
        <image>
          <format>B8G8R8</format>
          <width>640</width>
          <height>480</height>
        </image>
        <clip>
          <near>0.05</near>
          <far>8.0</far>
        </clip>
      </camera>
      <plugin filename="libgazebo_ros_camera.so" name="back_camera_camera_controller">
        <camera_name>back_camera</camera_name>
        <frame_name>back_camera_link_optical</frame_name>
        <hack_baseline>0.07</hack_baseline>
        <min_depth>0.4</min_depth>
        <max_depth>6</max_depth>
        <ros>
          
          <qos>
            <topic name="back_camera/points">
              <publisher>
                <reliability>best_effort</reliability>
                <!-- Change to 'best_effort' -->
                <durability>volatile</durability>
                <!-- Optionally set durability -->
              </publisher>
            </topic>
          </qos>
        </ros>
      </plugin>
    </sensor>
  </gazebo>
  <!-- Define the joint and link once -->
  <joint name="gps_base_joint" type="fixed">
    <parent link="base_link"/>
    <child link="gps_base_link"/>
    <origin rpy="0.0 0.0 0.0" xyz="-0.25 0.0 0.33"/>
  </joint>
  <link name="gps_base_link"/>
  <gazebo reference="gps_base_link">
    <sensor name="gps_base_gps" type="gps">
      <plugin filename="libgazebo_ros_gps_sensor.so" name="gps_base_controller">
        <ros>
          <!-- <namespace>$(arg prefix)</namespace> -->
          <remapping>~/out:=gps_base/fix</remapping>
        </ros>
        <frame_name>gps_base_link</frame_name>
      </plugin>
      <always_on>true</always_on>
      <update_rate>10</update_rate>
    </sensor>
  </gazebo>
  <!-- <xacro:hunter_gps name="$(arg prefix)back_antenna" is_sim="$(arg is_sim)" x="-0.5" y="-0.245" z="0.80"/> -->
  <!-- <xacro:hunter_gps name="$(arg prefix)front_antenna" is_sim="$(arg is_sim)" x="0.5" y="-0.245" z="0.80"/> -->
  <link name="front_lidar_link">
    <inertial>
      <origin rpy="0 0 0" xyz="0 0 0"/>
      <mass value="0.4"/>
      <inertia ixx="0.00045333333333333337" ixy="0.0" ixz="0.0" iyy="0.00045333333333333337" iyz="0.0" izz="0.00023999999999999998"/>
    </inertial>
    <visual>
      <geometry>
        <mesh filename="file:///home/ros/aoc_strawberry_scenario_ws/install/gazebo_multisim_server/share/gazebo_multisim_server/meshes/livox360.dae"/>
      </geometry>
    </visual>
    <collision>
      <geometry>
        <mesh filename="file:///home/ros/aoc_strawberry_scenario_ws/install/gazebo_multisim_server/share/gazebo_multisim_server/meshes/livox360.dae"/>
      </geometry>
    </collision>
  </link>
  <joint name="front_lidar_link_joint" type="fixed">
    <parent link="base_link"/>
    <child link="front_lidar_link"/>
    <origin rpy="0 0 0" xyz="0.615 0.28 0.33"/>
  </joint>
  <gazebo reference="front_lidar_link">
    <sensor name="front_lidar_link" type="ray">
      <!-- <pose>${origin_xyz} ${origin_rpy}</pose> -->
      <pose>0 0 0 0 0 0</pose>
      <visualize>true</visualize>
      <update_rate>10</update_rate>
      <plugin filename="libros2_livox.so" name="front_lidar_link_plugin">
        <ray>
          <scan>
            <horizontal>
              <samples>100</samples>
              <resolution>1</resolution>
              <min_angle>0</min_angle>
              <max_angle>6.2831852</max_angle>
            </horizontal>
            <vertical>
              <samples>360</samples>
              <resolution>1</resolution>
              <min_angle>-0.12601276984444446</min_angle>
              <max_angle>0.9637707965111111</max_angle>
            </vertical>
          </scan>
          <range>
            <min>0.1</min>
            <max>100.0</max>
            <resolution>0.002</resolution>
          </range>
          <noise>
            <type>gaussian</type>
            <mean>0.0</mean>
            <stddev>0.01</stddev>
          </noise>
        </ray>
        <visualize>false</visualize>
        <samples>10000</samples>
        <downsample>10</downsample>
        <csv_file_name>/home/ros/aoc_strawberry_scenario_ws/install/gazebo_multisim_server/share/gazebo_multisim_server/csv/mid360.csv</csv_file_name>
        <topic>front_lidar/points</topic>
      </plugin>
    </sensor>
  </gazebo>
  <link name="back_lidar_link">
    <inertial>
      <origin rpy="0 0 0" xyz="0 0 0"/>
      <mass value="0.4"/>
      <inertia ixx="0.00045333333333333337" ixy="0.0" ixz="0.0" iyy="0.00045333333333333337" iyz="0.0" izz="0.00023999999999999998"/>
    </inertial>
    <visual>
      <geometry>
        <mesh filename="file:///home/ros/aoc_strawberry_scenario_ws/install/gazebo_multisim_server/share/gazebo_multisim_server/meshes/livox360.dae"/>
      </geometry>
    </visual>
    <collision>
      <geometry>
        <mesh filename="file:///home/ros/aoc_strawberry_scenario_ws/install/gazebo_multisim_server/share/gazebo_multisim_server/meshes/livox360.dae"/>
      </geometry>
    </collision>
  </link>
  <joint name="back_lidar_link_joint" type="fixed">
    <parent link="base_link"/>
    <child link="back_lidar_link"/>
    <origin rpy="0 0 3.14159" xyz="-0.615 -0.28 0.33"/>
  </joint>
  <gazebo reference="back_lidar_link">
    <sensor name="back_lidar_link" type="ray">
      <!-- <pose>${origin_xyz} ${origin_rpy}</pose> -->
      <pose>0 0 0 0 0 0</pose>
      <visualize>true</visualize>
      <update_rate>10</update_rate>
      <plugin filename="libros2_livox.so" name="back_lidar_link_plugin">
        <ray>
          <scan>
            <horizontal>
              <samples>100</samples>
              <resolution>1</resolution>
              <min_angle>0</min_angle>
              <max_angle>6.2831852</max_angle>
            </horizontal>
            <vertical>
              <samples>360</samples>
              <resolution>1</resolution>
              <min_angle>-0.12601276984444446</min_angle>
              <max_angle>0.9637707965111111</max_angle>
            </vertical>
          </scan>
          <range>
            <min>0.1</min>
            <max>100.0</max>
            <resolution>0.002</resolution>
          </range>
          <noise>
            <type>gaussian</type>
            <mean>0.0</mean>
            <stddev>0.01</stddev>
          </noise>
        </ray>
        <visualize>false</visualize>
        <samples>10000</samples>
        <downsample>10</downsample>
        <csv_file_name>/home/ros/aoc_strawberry_scenario_ws/install/gazebo_multisim_server/share/gazebo_multisim_server/csv/mid360.csv</csv_file_name>
        <topic>back_lidar/points</topic>
      </plugin>
    </sensor>
  </gazebo>
</robot>
